Workbook

Sheet ppk
B1: fixed
B2: id_user | C2: email
B3: 3 | C3: sofjan@ecampus.ut.ac.id
B4: 4 | C4: aguss@ecampus.ut.ac.id
B5: 11 | C5: agussm@ecampus.ut.ac.id
B6: 17 | C6: ajoko@ecampus.ut.ac.id
B7: 18 | C7: dimas@ecampus.ut.ac.id
B8: 22 | C8: dewi@ecampus.ut.ac.id
B9: 24 | C9: any@ecampus.ut.ac.id
B10: 47 | C10: srismu@ecampus.ut.ac.id
B11: 48 | C11: enceng@ecampus.ut.ac.id
B12: 49 | C12: priono@ecampus.ut.ac.id
B13: 52 | C13: erusyana@ecampus.ut.ac.id
B14: 53 | C14: atatang@ecampus.ut.ac.id
... B67: 32644 | C67: bambangy@ecampus.ut.ac.id

Sheet pp
B1: fixed
B2: id_user | C2: email
B3: 9 | C3: susiloe@ecampus.ut.ac.id
B4: 43 | C4: yandriana@ecampus.ut.ac.id
B5: 93 | C5: burhanm@ecampus.ut.ac.id
B6: 94 | C6: fadilla@ecampus.ut.ac.id
B7: 97 | C7: efita@ecampus.ut.ac.id
B8: 99 | C8: ansariw@ecampus.ut.ac.id
B9: 103 | C9: trim@ecampus.ut.ac.id
B10: 107 | C10: hudi@ecampus.ut.ac.id
B11: 108 | C11: imamdh@ecampus.ut.ac.id
B12: 121 | C12: ahyar_hanubun@ecampus.ut.ac.id
B13: 200 | C13: sugiyonos@ecampus.ut.ac.id
B14: 782 | C14: desca@ecampus.ut.ac.id
... B67: 32720 | C67: jokorw@ecampus.ut.ac.id

Sheet PK
B2: 1 | C2: 1 | D2: Ihrom Lestari | E2: =VLOOKUP(F2,helper_user_kodeunit[[email]:[nama2]], 3, FALSE) -> Ihrom Lestari | F2: =VLOOKUP(D2,njei!$A$3:$C$2373,3,FALSE) -> ihrom-lestari@ecampus.ut.ac.id | G2: =VLOOKUP(F2,email_id[],2,FALSE) -> 198 | H2: PK-PBJ Kegiatan Pendukung Direktorat Manajemen Aset, Umum, dan Pengadaan Barang/Jasa
B3: 2 | C3: 2 | D3: Diki Senjaya Rohmatullah | E3: =VLOOKUP(F3,helper_user_kodeunit[[email]:[nama2]], 3, FALSE) -> Diki Senjaya Rohmatullah | F3: =VLOOKUP(D3,njei!$A$3:$C$2373,3,FALSE) -> dikisenjaya@ecampus.ut.ac.id | G3: =VLOOKUP(F3,email_id[],2,FALSE) -> 554
B4: 3 | C4: 3 | D4: Rinaldy Akbar Rifai | E4: =VLOOKUP(F4,helper_user_kodeunit[[email]:[nama2]], 3, FALSE) -> Rinaldy Akbar Rifai | F4: =VLOOKUP(D4,njei!$A$3:$C$2373,3,FALSE) -> rinaldy@ecampus.ut.ac.id | G4: =VLOOKUP(F4,email_id[],2,FALSE) -> 32679
B5: 4 | C5: 4 | D5: Fantio Isdeo Margono | E5: =VLOOKUP(F5,helper_user_kodeunit[[email]:[nama2]], 3, FALSE) -> Fantio Isdeo Margono | F5: =VLOOKUP(D5,njei!$A$3:$C$2373,3,FALSE) -> isdeo@ecampus.ut.ac.id | G5: =VLOOKUP(F5,email_id[],2,FALSE) -> 33000
B6: 5 | C6: 5 | D6: Muhammad Muqsith Arsyad | E6: =VLOOKUP(F6,helper_user_kodeunit[[email]:[nama2]], 3, FALSE) -> Muhammad Muqsith Arsyad | F6: =VLOOKUP(D6,njei!$A$3:$C$2373,3,FALSE) -> muqsith@ecampus.ut.ac.id | G6: =VLOOKUP(F6,email_id[],2,FALSE) -> 33001
B7: 6 | C7: 1 | D7: Sigit Purnomo | E7: =VLOOKUP(F7,helper_user_kodeunit[[email]:[nama2]], 3, FALSE) -> Sigit Purnomo | F7: =VLOOKUP(D7,njei!$A$3:$C$2373,3,FALSE) -> sigitp@ecampus.ut.ac.id | G7: =VLOOKUP(F7,email_id[],2,FALSE) -> 29 | H7: PK-PBJ Kegiatan Pendukung Sekretariat Universitas
B8: 7 | C8: 2 | D8: Endi Rekarti | E8: =VLOOKUP(F8,helper_user_kodeunit[[email]:[nama2]], 3, FALSE) -> Endi Rekarti | F8: =VLOOKUP(D8,njei!$A$3:$C$2373,3,FALSE) -> endirekarti@ecampus.ut.ac.id | G8: =VLOOKUP(F8,email_id[],2,FALSE) -> 33002
B9: 8 | C9: 3 | D9: Muhamad Farhan Wirakusuma | E9: =VLOOKUP(F9,helper_user_kodeunit[[email]:[nama2]], 3, FALSE) -> Muhamad Farhan Wirakusuma | F9: =VLOOKUP(D9,njei!$A$3:$C$2373,3,FALSE) -> muhamad.farhan@ecampus.ut.ac.id | G9: =VLOOKUP(F9,email_id[],2,FALSE) -> 33003
B10: 9 | C10: 1 | D10: Eka Wirajuang Daurrohmah | E10: =VLOOKUP(F10,helper_user_kodeunit[[email]:[nama2]], 3, FALSE) -> Eka Wirajuang Daurrohmah | F10: =VLOOKUP(D10,njei!$A$3:$C$2373,3,FALSE) -> ekawirajuang@ecampus.ut.ac.id | G10: =VLOOKUP(F10,email_id[],2,FALSE) -> 12656 | H10: PK-PBJ Kegiatan Pendukung Fakultas Ekonomi dan Bisnis
B11: 10 | C11: 2 | D11: Hasta Dwi Pradana | E11: =VLOOKUP(F11,helper_user_kodeunit[[email]:[nama2]], 3, FALSE) -> Hasta Dwi Pradana | F11: =VLOOKUP(D11,njei!$A$3:$C$2373,3,FALSE) -> hasta@ecampus.ut.ac.id | G11: =VLOOKUP(F11,email_id[],2,FALSE) -> 31420
B12: 11 | C12: 3 | D12: Nindya Farah Dwi Puspitasari | E12: =VLOOKUP(F12,helper_user_kodeunit[[email]:[nama2]], 3, FALSE) -> Nindya Farah Dwi Puspitasari | F12: =VLOOKUP(D12,njei!$A$3:$C$2373,3,FALSE) -> nindyafarah@ecampus.ut.ac.id | G12: =VLOOKUP(F12,email_id[],2,FALSE) -> 12608
B13: 12 | C13: 1 | D13: Yadi Apriyadi | E13: =VLOOKUP(F13,helper_user_kodeunit[[email]:[nama2]], 3, FALSE) -> Yadi Apriyadi | F13: =VLOOKUP(D13,njei!$A$3:$C$2373,3,FALSE) -> yadiap@ecampus.ut.ac.id | G13: =VLOOKUP(F13,email_id[],2,FALSE) -> 122 | H13: PK-PBJ Kegiatan Pendukung Fakultas Hukum, Ilmu Sosial, dan Ilmu Politik
B14: 13 | C14: 2 | D14: Erika Darmayanti | E14: =VLOOKUP(F14,helper_user_kodeunit[[email]:[nama2]], 3, FALSE) -> Erika Darmayanti | F14: =VLOOKUP(D14,njei!$A$3:$C$2373,3,FALSE) -> erika@ecampus.ut.ac.id | G14: =VLOOKUP(F14,email_id[],2,FALSE) -> 33004
B15: 14 | C15: 3 | D15: Nining Setianingsih | E15: =VLOOKUP(F15,helper_user_kodeunit[[email]:[nama2]], 3, FALSE) -> Nining Setianingsih | F15: =VLOOKUP(D15,njei!$A$3:$C$2373,3,FALSE) -> nining@ecampus.ut.ac.id | G15: =VLOOKUP(F15,email_id[],2,FALSE) -> 33005
B16: 15 | C16: 1 | D16: Isti Rokhiyah | E16: =VLOOKUP(F16,helper_user_kodeunit[[email]:[nama2]], 3, FALSE) -> Isti Rokhiyah | F16: =VLOOKUP(D16,njei!$A$3:$C$2373,3,FALSE) -> isti@ecampus.ut.ac.id | G16: =VLOOKUP(F16,email_id[],2,FALSE) -> 33006 | H16: PK-PBJ Kegiatan Pendukung Fakultas Keguruan dan Ilmu Pendidikan
B17: 16 | C17: 2 | D17: Leonard Raden Hutasoit | E17: =VLOOKUP(F17,helper_user_kodeunit[[email]:[nama2]], 3, FALSE) -> Leonard Raden Hutasoit | F17: =VLOOKUP(D17,njei!$A$3:$C$2373,3,FALSE) -> leonard_rh@ecampus.ut.ac.id | G17: =VLOOKUP(F17,email_id[],2,FALSE) -> 33007
B18: 17 | C18: 3 | D18: Supriyatno | E18: =VLOOKUP(F18,helper_user_kodeunit[[email]:[nama2]], 3, FALSE) -> Supriyatno | F18: =VLOOKUP(D18,njei!$A$3:$C$2373,3,FALSE) -> supripk@ecampus.ut.ac.id | G18: =VLOOKUP(F18,email_id[],2,FALSE) -> 12211
B19: 18 | C19: 1 | D19: Ariyanti Hartari | E19: =VLOOKUP(F19,helper_user_kodeunit[[email]:[nama2]], 3, FALSE) -> Ariyanti Hartari | F19: =VLOOKUP(D19,njei!$A$3:$C$2373,3,FALSE) -> ariyanti@ecampus.ut.ac.id | G19: =VLOOKUP(F19,email_id[],2,FALSE) -> 12911
B20: 19 | C20: 2 | D20: Faujatul Hasanah | E20: =VLOOKUP(F20,helper_user_kodeunit[[email]:[nama2]], 3, FALSE) -> Faujatul Hasanah | F20: =VLOOKUP(D20,njei!$A$3:$C$2373,3,FALSE) -> faujatul.hasanah@ecampus.ut.ac.id | G20: =VLOOKUP(F20,email_id[],2,FALSE) -> 33008 | H20: PK-PBJ Kegiatan Pendukung Fakultas Sains dan Teknologi
B21: 20 | C21: 3 | D21: Naufal Rifky Cahya | E21: =VLOOKUP(F21,helper_user_kodeunit[[email]:[nama2]], 3, FALSE) -> Naufal Rifky Cahya | F21: =VLOOKUP(D21,njei!$A$3:$C$2373,3,FALSE) -> naufal_rc@ecampus.ut.ac.id | G21: =VLOOKUP(F21,email_id[],2,FALSE) -> 33009
B22: 21 | C22: 4 | D22: Zulfa | E22: =VLOOKUP(F22,helper_user_kodeunit[[email]:[nama2]], 3, FALSE) -> Zulfa | F22: =VLOOKUP(D22,njei!$A$3:$C$2373,3,FALSE) -> zulfa@ecampus.ut.ac.id | G22: =VLOOKUP(F22,email_id[],2,FALSE) -> 12853
B23: 22 | C23: 5 | D23: Arie Aryanto | E23: =VLOOKUP(F23,helper_user_kodeunit[[email]:[nama2]], 3, FALSE) -> Arie Aryanto | F23: =VLOOKUP(D23,njei!$A$3:$C$2373,3,FALSE) -> arie.aryanto@ecampus.ut.ac.id | G23: =VLOOKUP(F23,email_id[],2,FALSE) -> 33010
B24: 23 | C24: 1 | D24: Dewi Suranti | E24: =VLOOKUP(F24,helper_user_kodeunit[[email]:[nama2]], 3, FALSE) -> Dewi Suranti | F24: =VLOOKUP(D24,njei!$A$3:$C$2373,3,FALSE) -> dewis@ecampus.ut.ac.id | G24: =VLOOKUP(F24,email_id[],2,FALSE) -> 33011 | H24: PK-PBJ Kegiatan Pendukung Sekolah Pascasarjana
B25: 24 | C25: 2 | D25: Julianto Mardimpu Pasaribu | E25: =VLOOKUP(F25,helper_user_kodeunit[[email]:[nama2]], 3, FALSE) -> Julianto Mardimpu Pasaribu | F25: =VLOOKUP(D25,njei!$A$3:$C$2373,3,FALSE) -> julianto@ecampus.ut.ac.id | G25: =VLOOKUP(F25,email_id[],2,FALSE) -> 33012
B26: 25 | C26: 3 | D26: Suwardi | E26: =VLOOKUP(F26,helper_user_kodeunit[[email]:[nama2]], 3, FALSE) -> Suwardi | F26: =VLOOKUP(D26,njei!$A$3:$C$2373,3,FALSE) -> wardi@ecampus.ut.ac.id | G26: =VLOOKUP(F26,email_id[],2,FALSE) -> 12382
B27: 26 | C27: 1 | D27: Andi Harmoko Arifin | E27: =VLOOKUP(F27,helper_user_kodeunit[[email]:[nama2]], 3, FALSE) -> Andi Harmoko Arifin | F27: =VLOOKUP(D27,njei!$A$3:$C$2373,3,FALSE) -> andiharmoko@ecampus.ut.ac.id | G27: =VLOOKUP(F27,email_id[],2,FALSE) -> 33013 | H27: PK-PBJ Kegiatan Pendukung Sekolah Vokasi
B28: 27 | C28: 2 | D28: Habiburrahman | E28: =VLOOKUP(F28,helper_user_kodeunit[[email]:[nama2]], 3, FALSE) -> Habiburrahman | F28: =VLOOKUP(D28,njei!$A$3:$C$2373,3,FALSE) -> habiburrahman@ecampus.ut.ac.id | G28: =VLOOKUP(F28,email_id[],2,FALSE) -> 33014
B29: 28 | C29: 3 | D29: Nabila Meutia Pratiwi | E29: =VLOOKUP(F29,helper_user_kodeunit[[email]:[nama2]], 3, FALSE) -> Nabila Meutia Pratiwi | F29: =VLOOKUP(D29,njei!$A$3:$C$2373,3,FALSE) -> nabila@ecampus.ut.ac.id | G29: =VLOOKUP(F29,email_id[],2,FALSE) -> 12602
B30: 29 | C30: 1 | D30: Mirza Permana | E30: =VLOOKUP(F30,helper_user_kodeunit[[email]:[nama2]], 3, FALSE) -> Mirza Permana | F30: =VLOOKUP(D30,njei!$A$3:$C$2373,3,FALSE) -> permanamirza@ecampus.ut.ac.id | G30: =VLOOKUP(F30,email_id[],2,FALSE) -> 33015 | H30: PK-PBJ Kegiatan Pendukung Lembaga Penelitian dan Pengabdian kepada
B31: 30 | C31: 2 | D31: Suhartono | E31: =VLOOKUP(F31,helper_user_kodeunit[[email]:[nama2]], 3, FALSE) -> Suhartono | F31: hart@ecampus.ut.ac.id | G31: =VLOOKUP(F31,email_id[],2,FALSE) -> #N/A | H31: Masyarakat
B32: 31 | C32: 3 | D32: Tessa Melanie Wulandari | E32: =VLOOKUP(F32,helper_user_kodeunit[[email]:[nama2]], 3, FALSE) -> Tessa Melanie Wulandari | F32: =VLOOKUP(D32,njei!$A$3:$C$2373,3,FALSE) -> tessa@ecampus.ut.ac.id | G32: =VLOOKUP(F32,email_id[],2,FALSE) -> 33016
B33: 32 | C33: 1 | D33: Abdul Rohim | E33: =VLOOKUP(F33,helper_user_kodeunit[[email]:[nama2]], 3, FALSE) -> Abdul Rohim | F33: =VLOOKUP(D33,njei!$A$3:$C$2373,3,FALSE) -> abdulr@ecampus.ut.ac.id | G33: =VLOOKUP(F33,email_id[],2,FALSE) -> 12213 | H33: PK-PBJ Kegiatan Pendukung Direktorat Administrasi Akademik dan Kelulusan
B34: 33 | C34: 2 | D34: Bondan Haryono | E34: =VLOOKUP(F34,helper_user_kodeunit[[email]:[nama2]], 3, FALSE) -> Bondan Haryono | F34: =VLOOKUP(D34,njei!$A$3:$C$2373,3,FALSE) -> bondan@ecampus.ut.ac.id | G34: =VLOOKUP(F34,email_id[],2,FALSE) -> 12215
B35: 34 | C35: 3 | D35: Rizki Annisha | E35: =VLOOKUP(F35,helper_user_kodeunit[[email]:[nama2]], 3, FALSE) -> Rizki Annisha | F35: =VLOOKUP(D35,njei!$A$3:$C$2373,3,FALSE) -> rizki@ecampus.ut.ac.id | G35: =VLOOKUP(F35,email_id[],2,FALSE) -> 33017
B36: 35 | C36: 1 | D36: Agung Wicaksono | E36: =VLOOKUP(F36,helper_user_kodeunit[[email]:[nama2]], 3, FALSE) -> Agung Wicaksono | F36: =VLOOKUP(D36,njei!$A$3:$C$2373,3,FALSE) -> agungw@ecampus.ut.ac.id | G36: =VLOOKUP(F36,email_id[],2,FALSE) -> 12970 | H36: PK-PBJ Kegiatan Pendukung Direktorat Teknologi Digital
B37: 36 | C37: 2 | D37: Deni Rudiana Aprizal | E37: =VLOOKUP(F37,helper_user_kodeunit[[email]:[nama2]], 3, FALSE) -> Deni Rudiana Aprizal | F37: =VLOOKUP(D37,njei!$A$3:$C$2373,3,FALSE) -> deni@ecampus.ut.ac.id | G37: =VLOOKUP(F37,email_id[],2,FALSE) -> 12971
E38: =VLOOKUP(F38,helper_user_kodeunit[[email]:[nama2]], 3, FALSE) -> #N/A
B39: 37 | C39: 3 | D39: Iwan Susanto | E39: =VLOOKUP(F39,helper_user_kodeunit[[email]:[nama2]], 3, FALSE) -> Iwan Susanto | F39: =VLOOKUP(D39,njei!$A$3:$C$2373,3,FALSE) -> iwans@ecampus.ut.ac.id | G39: =VLOOKUP(F39,email_id[],2,FALSE) -> 12969
B40: 38 | C40: 1 | D40: Yudhi Prasetiyo | E40: =VLOOKUP(F40,helper_user_kodeunit[[email]:[nama2]], 3, FALSE) -> Yudhi Prasetiyo | F40: =VLOOKUP(D40,njei!$A$3:$C$2373,3,FALSE) -> yudhiprasetiyo@ecampus.ut.ac.id | G40: =VLOOKUP(F40,email_id[],2,FALSE) -> 33018 | H40: PK-PBJ Kegiatan Pendukung Pusat Komunikasi Publik dan Kerja Sama
B41: 39 | C41: 2 | D41: Een Setyowati | E41: =VLOOKUP(F41,helper_user_kodeunit[[email]:[nama2]], 3, FALSE) -> Een Setyowati | F41: =VLOOKUP(D41,njei!$A$3:$C$2373,3,FALSE) -> een.setyowati@ecampus.ut.ac.id | G41: =VLOOKUP(F41,email_id[],2,FALSE) -> 33019
...

Sheet verif
B2: id_user | C2: nama | D2: email
B3: 32679 | C3: Rinaldy Akbar Rifai | D3: rinaldy@ecampus.ut.ac.id | E3: 119870707202307101
B4: 198 | C4: Ihrom Lestari | D4: ihrom-lestari@ecampus.ut.ac.id | E4: 119930606202403101
B5: 554 | C5: Diki Senjaya Rohmatullah | D5: dikisenjaya@ecampus.ut.ac.id | E5: 119950921202312101
B6: 12345 | C6: Al Kharisma Rizky NR | D6: alkharisma@ecampus.ut.ac.id | E6: 119900201202312201
B7: 196 | C7: Fajar Ichwan | D7: fajar-ichwan@ecampus.ut.ac.id | E7: 219970223202404101

Sheet Sheet3
B1: Ihrom Lestari | C1: ihrom-lestari@ecampus.ut.ac.id | D1: =VLOOKUP(C1,helper_user_kodeunit_202603250953[[email]:[nip]],3,FALSE) -> 119930606202403101 | E1: =C1&"::"&B1&"::"&D1 -> ihrom-lestari@ecampus.ut.ac.id::Ihrom Lestari::119930606202403101 | F1: 198
B2: Diki Senjaya Rohmatullah | C2: dikisenjaya@ecampus.ut.ac.id | D2: =VLOOKUP(C2,helper_user_kodeunit_202603250953[[email]:[nip]],3,FALSE) -> 119950921202312101 | E2: =C2&"::"&B2&"::"&D2 -> dikisenjaya@ecampus.ut.ac.id::Diki Senjaya Rohmatullah::119950921202312101 | F2: 198
B3: Rinaldy Akbar Rifai | C3: rinaldy@ecampus.ut.ac.id | D3: =VLOOKUP(C3,helper_user_kodeunit_202603250953[[email]:[nip]],3,FALSE) -> 119870707202307101 | E3: =C3&"::"&B3&"::"&D3 -> rinaldy@ecampus.ut.ac.id::Rinaldy Akbar Rifai::119870707202307101 | F3: 198
B4: Fantio Isdeo Margono | C4: isdeo@ecampus.ut.ac.id | D4: =VLOOKUP(C4,helper_user_kodeunit_202603250953[[email]:[nip]],3,FALSE) -> 119970603202403101 | E4: =C4&"::"&B4&"::"&D4 -> isdeo@ecampus.ut.ac.id::Fantio Isdeo Margono::119970603202403101 | F4: 198
B5: Muhammad Muqsith Arsyad | C5: muqsith@ecampus.ut.ac.id | D5: =VLOOKUP(C5,helper_user_kodeunit_202603250953[[email]:[nip]],3,FALSE) -> 119971124202403101 | E5: =C5&"::"&B5&"::"&D5 -> muqsith@ecampus.ut.ac.id::Muhammad Muqsith Arsyad::119971124202403101 | F5: 198
B6: Sigit Purnomo | C6: sigitp@ecampus.ut.ac.id | D6: =VLOOKUP(C6,helper_user_kodeunit_202603250953[[email]:[nip]],3,FALSE) -> 198003222005011003 | E6: =C6&"::"&B6&"::"&D6 -> sigitp@ecampus.ut.ac.id::Sigit Purnomo::198003222005011003 | F6: 198
B7: Endi Rekarti | C7: endirekarti@ecampus.ut.ac.id | D7: =VLOOKUP(C7,helper_user_kodeunit_202603250953[[email]:[nip]],3,FALSE) -> 119670619202403101 | E7: =C7&"::"&B7&"::"&D7 -> endirekarti@ecampus.ut.ac.id::Endi Rekarti::119670619202403101 | F7: 198
B8: Muhamad Farhan Wirakusuma | C8: muhamad.farhan@ecampus.ut.ac.id | D8: =VLOOKUP(C8,helper_user_kodeunit_202603250953[[email]:[nip]],3,FALSE) -> 120011113202509101 | E8: =C8&"::"&B8&"::"&D8 -> muhamad.farhan@ecampus.ut.ac.id::Muhamad Farhan Wirakusuma::120011113202509101 | F8: 198
B9: Eka Wirajuang Daurrohmah | C9: ekawirajuang@ecampus.ut.ac.id | D9: =VLOOKUP(C9,helper_user_kodeunit_202603250953[[email]:[nip]],3,FALSE) -> 199408062020122015 | E9: =C9&"::"&B9&"::"&D9 -> ekawirajuang@ecampus.ut.ac.id::Eka Wirajuang Daurrohmah::199408062020122015 | F9: 198
B10: Hasta Dwi Pradana | C10: hasta@ecampus.ut.ac.id | D10: =VLOOKUP(C10,helper_user_kodeunit_202603250953[[email]:[nip]],3,FALSE) -> 198911052022031005 | E10: =C10&"::"&B10&"::"&D10 -> hasta@ecampus.ut.ac.id::Hasta Dwi Pradana::198911052022031005 | F10: 198
B11: Nindya Farah Dwi Puspitasari | C11: nindyafarah@ecampus.ut.ac.id | D11: =VLOOKUP(C11,helper_user_kodeunit_202603250953[[email]:[nip]],3,FALSE) -> 199205072019032025 | E11: =C11&"::"&B11&"::"&D11 -> nindyafarah@ecampus.ut.ac.id::Nindya Farah Dwi Puspitasari::199205072019032025 | F11: 198
B12: Yadi Apriyadi | C12: yadiap@ecampus.ut.ac.id | D12: =VLOOKUP(C12,helper_user_kodeunit_202603250953[[email]:[nip]],3,FALSE) -> 197804182006041002 | E12: =C12&"::"&B12&"::"&D12 -> yadiap@ecampus.ut.ac.id::Yadi Apriyadi::197804182006041002 | F12: 198
... B36: Deni Rudiana Aprizal | C36: deni@ecampus.ut.ac.id | D36: =VLOOKUP(C36,helper_user_kodeunit_202603250953[[email]:[nip]],3,FALSE) -> 198904062014041002 | E36: =C36&"::"&B36&"::"&D36 -> deni@ecampus.ut.ac.id::Deni Rudiana Aprizal::198904062014041002 | F36: 198
B37: #N/A | D37: =VLOOKUP(C37,helper_user_kodeunit_202603250953[[email]:[nip]],3,FALSE) -> #N/A | E37: =C37&"::"&B37&"::"&D37 -> #N/A | F37: 198
B38: Iwan Susanto | C38: iwans@ecampus.ut.ac.id | D38: =VLOOKUP(C38,helper_user_kodeunit_202603250953[[email]:[nip]],3,FALSE) -> 198004062009121003 | E38: =C38&"::"&B38&"::"&D38 -> iwans@ecampus.ut.ac.id::Iwan Susanto::198004062009121003 | F38: 198
B39: Yudhi Prasetiyo | C39: yudhiprasetiyo@ecampus.ut.ac.id | D39: =VLOOKUP(C39,helper_user_kodeunit_202603250953[[email]:[nip]],3,FALSE) -> 199403262022031015 | E39: =C39&"::"&B39&"::"&D39 -> yudhiprasetiyo@ecampus.ut.ac.id::Yudhi Prasetiyo::199403262022031015 | F39: 198
B40: Een Setyowati | C40: een.setyowati@ecampus.ut.ac.id | D40: =VLOOKUP(C40,helper_user_kodeunit_202603250953[[email]:[nip]],3,FALSE) -> 120030307202509201 | E40: =C40&"::"&B40&"::"&D40 -> een.setyowati@ecampus.ut.ac.id::Een Setyowati::120030307202509201 | F40: 198
B41: Muhammad Sayyid Assobri | C41: muhammad.sayyid@ecampus.ut.ac.id | D41: =VLOOKUP(C41,helper_user_kodeunit_202603250953[[email]:[nip]],3,FALSE) -> 119990903202509102 | E41: =C41&"::"&B41&"::"&D41 -> muhammad.sayyid@ecampus.ut.ac.id::Muhammad Sayyid Assobri::119990903202509102 | F41: 198
B42: Ahmad Binadi, SE. | C42: bina@ecampus.ut.ac.id | D42: =VLOOKUP(C42,helper_user_kodeunit_202603250953[[email]:[nip]],3,FALSE) -> 197106032003121001 | E42: =C42&"::"&B42&"::"&D42 -> bina@ecampus.ut.ac.id::Ahmad Binadi, SE.::197106032003121001 | F42: 198
B43: Benny Triatmo | C43: benie@ecampus.ut.ac.id | D43: =VLOOKUP(C43,helper_user_kodeunit_202603250953[[email]:[nip]],3,FALSE) -> 197801032010121004 | E43: =C43&"::"&B43&"::"&D43 -> benie@ecampus.ut.ac.id::Benny Triatmo::197801032010121004 | F43: 198
B44: Farkhan Raflesia | C44: farkhan.raflesia@ecampus.ut.ac.id | D44: =VLOOKUP(C44,helper_user_kodeunit_202603250953[[email]:[nip]],3,FALSE) -> 119960628202403101 | E44: =C44&"::"&B44&"::"&D44 -> farkhan.raflesia@ecampus.ut.ac.id::Farkhan Raflesia::119960628202403101 | F44: 198
B45: M. Ali Nurdin | C45: malin@ecampus.ut.ac.id | D45: =VLOOKUP(C45,helper_user_kodeunit_202603250953[[email]:[nip]],3,FALSE) -> 198203142005011001 | E45: =C45&"::"&B45&"::"&D45 -> malin@ecampus.ut.ac.id::M. Ali Nurdin::198203142005011001 | F45: 198
B46: Taufiqurrohman | C46: turrohman@ecampus.ut.ac.id | D46: =VLOOKUP(C46,helper_user_kodeunit_202603250953[[email]:[nip]],3,FALSE) -> 119960820202403102 | E46: =C46&"::"&B46&"::"&D46 -> turrohman@ecampus.ut.ac.id::Taufiqurrohman::119960820202403102 | F46: 198
B47: Hakim Usmanto | C47: hakim.usmanto@ecampus.ut.ac.id | D47: =VLOOKUP(C47,helper_user_kodeunit_202603250953[[email]:[nip]],3,FALSE) -> 119990719202509101 | E47: =C47&"::"&B47&"::"&D47 -> hakim.usmanto@ecampus.ut.ac.id::Hakim Usmanto::119990719202509101 | F47: 198
B48: Al Hafid | C48: alhafid@ecampus.ut.ac.id | D48: =VLOOKUP(C48,helper_user_kodeunit_202603250953[[email]:[nip]],3,FALSE) -> 198304252009121003 | E48: =C48&"::"&B48&"::"&D48 -> alhafid@ecampus.ut.ac.id::Al Hafid::198304252009121003 | F48: 198
B49: Candra Wibawa | C49: candraw@ecampus.ut.ac.id | D49: =VLOOKUP(C49,helper_user_kodeunit_202603250953[[email]:[nip]],3,FALSE) -> 197806182006041002 | E49: =C49&"::"&B49&"::"&D49 -> candraw@ecampus.ut.ac.id::Candra Wibawa::197806182006041002 | F49: 198
... B83: Debi | C83: debi.ut@ecampus.ut.ac.id | D83: =VLOOKUP(C83,helper_user_kodeunit_202603250953[[email]:[nip]],3,FALSE) -> 119910803202307101 | E83: =C83&"::"&B83&"::"&D83 -> debi.ut@ecampus.ut.ac.id::Debi::119910803202307101 | F83: 198
B84: #N/A | D84: =VLOOKUP(C84,helper_user_kodeunit_202603250953[[email]:[nip]],3,FALSE) -> #N/A | E84: =C84&"::"&B84&"::"&D84 -> #N/A | F84: 198
B85: Al Hafid | C85: alhafid@ecampus.ut.ac.id | D85: =VLOOKUP(C85,helper_user_kodeunit_202603250953[[email]:[nip]],3,FALSE) -> 198304252009121003 | E85: =C85&"::"&B85&"::"&D85 -> alhafid@ecampus.ut.ac.id::Al Hafid::198304252009121003 | F85: 198
B86: Candra Wibawa | C86: candraw@ecampus.ut.ac.id | D86: =VLOOKUP(C86,helper_user_kodeunit_202603250953[[email]:[nip]],3,FALSE) -> 197806182006041002 | E86: =C86&"::"&B86&"::"&D86 -> candraw@ecampus.ut.ac.id::Candra Wibawa::197806182006041002 | F86: 198
B87: Dony Darma Sagita | C87: donyds@ecampus.ut.ac.id | D87: =VLOOKUP(C87,helper_user_kodeunit_202603250953[[email]:[nip]],3,FALSE) -> 199011232024061002 | E87: =C87&"::"&B87&"::"&D87 -> donyds@ecampus.ut.ac.id::Dony Darma Sagita::199011232024061002 | F87: 198
B88: Sri Tatminingsih | C88: tatmi@ecampus.ut.ac.id | D88: =VLOOKUP(C88,helper_user_kodeunit_202603250953[[email]:[nip]],3,FALSE) -> 196710292005012001 | E88: =C88&"::"&B88&"::"&D88 -> tatmi@ecampus.ut.ac.id::Sri Tatminingsih::196710292005012001 | F88: 198
B89: Muktia Pramitasari | C89: muktia.pramitasari@ecampus.ut.ac.id | D89: =VLOOKUP(C89,helper_user_kodeunit_202603250953[[email]:[nip]],3,FALSE) -> 198902062022032005 | E89: =C89&"::"&B89&"::"&D89 -> muktia.pramitasari@ecampus.ut.ac.id::Muktia Pramitasari::198902062022032005 | F89: 198
B90: Monika Handayani | C90: monika@ecampus.ut.ac.id | D90: =VLOOKUP(C90,helper_user_kodeunit_202603250953[[email]:[nip]],3,FALSE) -> 199111172018032001 | E90: =C90&"::"&B90&"::"&D90 -> monika@ecampus.ut.ac.id::Monika Handayani::199111172018032001 | F90: 198
B91: Rif'at Shafwatul Anam | C91: rifat.official@ecampus.ut.ac.id | D91: =VLOOKUP(C91,helper_user_kodeunit_202603250953[[email]:[nip]],3,FALSE) -> 198504042023211019 | E91: =C91&"::"&B91&"::"&D91 -> rifat.official@ecampus.ut.ac.id::Rif'at Shafwatul Anam::198504042023211019 | F91: 198
B92: Ichwan | C92: ichwan@ecampus.ut.ac.id | D92: =VLOOKUP(C92,helper_user_kodeunit_202603250953[[email]:[nip]],3,FALSE) -> 196206061987031001 | E92: =C92&"::"&B92&"::"&D92 -> ichwan@ecampus.ut.ac.id::Ichwan::196206061987031001 | F92: 198
B93: I Made Gunawan Sanjaya | C93: madegs@ecampus.ut.ac.id | D93: =VLOOKUP(C93,helper_user_kodeunit_202603250953[[email]:[nip]],3,FALSE) -> 198705122010121006 | E93: =C93&"::"&B93&"::"&D93 -> madegs@ecampus.ut.ac.id::I Made Gunawan Sanjaya::198705122010121006 | F93: 198
B94: Teguh Muhammad Ilham | C94: teguhmi@ecampus.ut.ac.id | D94: =VLOOKUP(C94,helper_user_kodeunit_202603250953[[email]:[nip]],3,FALSE) -> 197908232005011001 | E94: =C94&"::"&B94&"::"&D94 -> teguhmi@ecampus.ut.ac.id::Teguh Muhammad Ilham::197908232005011001 | F94: 198
B95: Fajar Hijriyadi | C95: fajarh@ecampus.ut.ac.id | D95: =VLOOKUP(C95,helper_user_kodeunit_202603250953[[email]:[nip]],3,FALSE) -> 198409242010121005 | E95: =C95&"::"&B95&"::"&D95 -> fajarh@ecampus.ut.ac.id::Fajar Hijriyadi::198409242010121005 | F95: 198
B96: Teguh Budianto | C96: tegb@ecampus.ut.ac.id | D96: =VLOOKUP(C96,helper_user_kodeunit_202603250953[[email]:[nip]],3,FALSE) -> 197811262001121001 | E96: =C96&"::"&B96&"::"&D96 -> tegb@ecampus.ut.ac.id::Teguh Budianto::197811262001121001 | F96: 198
...

Sheet njei
A1: nama | B1: jabatan | C1: email | D1: id | E1: nama2
A2: Adrian Sutawijaya | B2: Wakil Rektor Bidang Keuangan, Sumber Daya, dan Umum | C2: adrian@ecampus.ut.ac.id | D2: 1 | E2: =helper_user_kodeunit[[#This Row],[nama]] -> Adrian Sutawijaya
A3: Ali Muktiyanto | B3: Rektor | C3: ali@ecampus.ut.ac.id | D3: 2 | E3: =helper_user_kodeunit[[#This Row],[nama]] -> Ali Muktiyanto
A4: Sofjan Aripin | B4: Kepala Pusat Perpustakaan dan Kearsipan | C4: sofjan@ecampus.ut.ac.id | D4: 3 | E4: =helper_user_kodeunit[[#This Row],[nama]] -> Sofjan Aripin
A5: Agus Santoso | B5: Direktur Universitas Terbuka Yogyakarta | C5: aguss@ecampus.ut.ac.id | D5: 4 | E5: =helper_user_kodeunit[[#This Row],[nama]] -> Agus Santoso
A6: Ake Wihadanto | B6: Sekretaris Majelis Wali Amanat | C6: ake@ecampus.ut.ac.id | D6: 6 | E6: =helper_user_kodeunit[[#This Row],[nama]] -> Ake Wihadanto
A7: Susilo Edi Prianto | B7: Asisten Manajer Keuangan, Sumber Daya, dan Umum pada Unit Laboratorium Terpadu | C7: susiloe@ecampus.ut.ac.id | D7: 9 | E7: =helper_user_kodeunit[[#This Row],[nama]] -> Susilo Edi Prianto
A8: Andi Suwandi | B8: Kepala Subdirektorat Rumah Tangga dan Pemeliharaan pada Direktorat Manajemen Aset, Umum, dan Pengadaan Barang/Jasa | C8: andis@ecampus.ut.ac.id | D8: 10 | E8: =helper_user_kodeunit[[#This Row],[nama]] -> Andi Suwandi
A9: Agus Saeful Mujab | B9: Kepala Pusat Distribusi Bahan Ajar | C9: agussm@ecampus.ut.ac.id | D9: 11 | E9: =helper_user_kodeunit[[#This Row],[nama]] -> Agus Saeful Mujab
A10: Paken Pandiangan | B10: Wakil Rektor Bidang Sistem Informasi, Layanan Jarak Jauh dan Alumni | C10: pakenp@ecampus.ut.ac.id | D10: 12 | E10: =helper_user_kodeunit[[#This Row],[nama]] -> Paken Pandiangan
A11: Timbul Pardede | B11: Plt. Ketua Lembaga Pendukung Pembelajaran Jarak Jauh | C11: timbul@ecampus.ut.ac.id | D11: 13 | E11: =helper_user_kodeunit[[#This Row],[nama]] -> Timbul Pardede
A12: Agus Joko Purwanto | B12: Direktur Universitas Terbuka Surakarta | C12: ajoko@ecampus.ut.ac.id | D12: 17 | E12: =helper_user_kodeunit[[#This Row],[nama]] -> Agus Joko Purwanto
A13: Dimas Agung Prasetyo | B13: Kepala Pusat Pengelolaan Pembelajaran | C13: dimas@ecampus.ut.ac.id | D13: 18 | E13: =helper_user_kodeunit[[#This Row],[nama]] -> Dimas Agung Prasetyo
... A1477: Joko Rizkie Widokarti | B1477: Wakil Direktur II Bidang Nonakademik pada Sekolah Vokasi | C1477: jokorw@ecampus.ut.ac.id | D1477: 32720 | E1477: =helper_user_kodeunit[[#This Row],[nama]] -> Joko Rizkie Widokarti
A1478: Mutia | B1478: Pengadministrasi Akademik | C1478: mutia@ecampus.ut.ac.id | E1478: =helper_user_kodeunit[[#This Row],[nama]] -> Mutia
A1479: Andry Olang | B1479: Pengadministrasi Pendukung Pembelajaran | C1479: AndryOlang@ecampus.ut.ac.id | E1479: =helper_user_kodeunit[[#This Row],[nama]] -> Andry Olang
A1480: Andriyansyah | B1480: Pengadministrasi Gudang | C1480: andriyansyah@ecampus.ut.ac.id | E1480: =helper_user_kodeunit[[#This Row],[nama]] -> Andriyansyah
A1481: Mutmainnah | B1481: Pengadministrasi Pembelajaran (masa percobaan) | C1481: mutmainnah@ecampus.ut.ac.id | E1481: =helper_user_kodeunit[[#This Row],[nama]] -> Mutmainnah
A1482: Mylanita Widya Putri | B1482: Pengelola Data Layanan Kemahasiswaan dan Pembelajaran | C1482: myl@ecampus.ut.ac.id | E1482: =helper_user_kodeunit[[#This Row],[nama]] -> Mylanita Widya Putri
A1483: Nabilah Aniq Fauziyah | B1483: Pengadministrasi Umum | C1483: nabilahaniq@ecampus.ut.ac.id | E1483: =helper_user_kodeunit[[#This Row],[nama]] -> Nabilah Aniq Fauziyah
A1484: Okky Agastya | B1484: Tenaga Front Desk | C1484: okkyagastya@ecampus.ut.ac.id | E1484: =helper_user_kodeunit[[#This Row],[nama]] -> Okky Agastya
A1485: Nabila Nur Safitri | B1485: Pengolah Data dan Informasi | C1485: nabila.safitri@ecampus.ut.ac.id | E1485: =helper_user_kodeunit[[#This Row],[nama]] -> Nabila Nur Safitri
A1486: Nabila Rizq Wildanbati | B1486: Pengadministrasi Peraturan Perundang-Undangan (masa percobaan) | C1486: nabila.rizq@ecampus.ut.ac.id | E1486: =helper_user_kodeunit[[#This Row],[nama]] -> Nabila Rizq Wildanbati
A1487: Nabila Zahra Nastiti | B1487: Pengolah Data | C1487: nabila.zahra@ecampus.ut.ac.id | E1487: =helper_user_kodeunit[[#This Row],[nama]] -> Nabila Zahra Nastiti
A1488: Nadhif Putera Nur Hibatullah | B1488: Pengadministrasi Umum | C1488: nadhif@ecampus.ut.ac.id | E1488: =helper_user_kodeunit[[#This Row],[nama]] -> Nadhif Putera Nur Hibatullah
A1489: Andrew Maikel Wohon | B1489: Pengelola Pendukung Pembelajaran | C1489: andrewwohon@ecampus.ut.ac.id | E1489: =helper_user_kodeunit[[#This Row],[nama]] -> Andrew Maikel Wohon
... A2372: Angga Aprianto | B2372: Asisten Lay Outer Tk. II | C2372: anggaapri@ecampus.ut.ac.id | E2372: =helper_user_kodeunit[[#This Row],[nama]] -> Angga Aprianto

Sheet Sheet6

Sheet nama_email
B3: Tessa Melanie Wulandari | C3: tessa@ecampus.ut.ac.id | F3: Manajer Perluasan Daya Jangkau, Registrasi, dan Ujian pada UT Jambi | G3: asyifqi@ecampus.ut.ac.id
B4: Eka Wirajuang Daurrohmah | C4: ekawirajuang@ecampus.ut.ac.id | F4: Manajer Pembelajaran, Kemahasiswaan, dan Alumni pada UT Padang | G4: adrianto@ecampus.ut.ac.id
B5: Suhartono | C5: tono@ecampus.ut.ac.id | F5: Manajer Pembelajaran, Kemahasiswaan, dan Alumni pada UT Jambi | G5: afriliani@ecampus.ut.ac.id
B6: Agung Wicaksono | C6: agungw@ecampus.ut.ac.id | F6: Manajer Perluasan Daya Jangkau, Registrasi, dan Ujian pada UT Pangkalpinang | G6: ahmadf@ecampus.ut.ac.id
B7: Deni Rudiana Aprizal | C7: deni@ecampus.ut.ac.id | F7: Manajer Pembelajaran, Kemahasiswaan, dan Alumni pada UT Batam | G7: alfatri.anom@ecampus.ut.ac.id
B8: Endi Rekarti | C8: endirekarti@ecampus.ut.ac.id | F8: Manajer Perluasan Daya Jangkau, Registrasi, dan Ujian pada UT Batam | G8: amrin-btm@ecampus.ut.ac.id
B9: Sigit Purnomo | C9: sigitp@ecampus.ut.ac.id | F9: Manajer Pembelajaran, Kemahasiswaan, dan Alumni pada UT Makassar | G9: andisuci@ecampus.ut.ac.id
B10: Ariyanti Hartari | C10: ariyanti@ecampus.ut.ac.id | F10: Manajer Pembelajaran, Kemahasiswaan, dan Alumni pada UT Pangkalpinang | G10: dessy@ecampus.ut.ac.id
B11: Mirza Permana | C11: permanamirza@ecampus.ut.ac.id | F11: Manajer Perluasan Daya Jangkau, Registrasi, dan Ujian pada UT Serang | G11: dyahpalupi@ecampus.ut.ac.id
B12: Suhartono | C12: hart@ecampus.ut.ac.id | F12: Manajer Pembelajaran, Kemahasiswaan, dan Alumni pada UT Jember | G12: lulu@ecampus.ut.ac.id
B13: Andi Harmoko Arifin | C13: andiharmoko@ecampus.ut.ac.id | F13: Manajer Perluasan Daya Jangkau, Registrasi, dan Ujian pada UT Bengkulu | G13: hasrul@ecampus.ut.ac.id
B14: Dewi Suranti | C14: dewis@ecampus.ut.ac.id | F14: Manajer Perluasan Daya Jangkau, Registrasi, dan Ujian pada UT Makassar | G14: jalil@ecampus.ut.ac.id
... B39: Zulfa | C39: zulfa@ecampus.ut.ac.id | F39: Manajer Perluasan Daya Jangkau, Registrasi, dan Ujian pada UT Purwokerto | G39: azis@ecampus.ut.ac.id
F40: Manajer Pembelajaran, Kemahasiswaan, dan Alumni pada UT Malang | G40: jonny@ecampus.ut.ac.id
F41: Manajer Pembelajaran, Kemahasiswaan, dan Alumni pada UT Bogor | G41: muh.komarudin@ecampus.ut.ac.id
F42: Manajer Pembelajaran, Kemahasiswaan, dan Alumni pada UT Medan | G42: nisha@ecampus.ut.ac.id
F43: Manajer Perluasan Daya Jangkau, Registrasi, dan Ujian pada UT Semarang | G43: siswandaru@ecampus.ut.ac.id
F44: Manajer Pembelajaran, Kemahasiswaan, dan Alumni pada UT Purwokerto | G44: tono@ecampus.ut.ac.id
F45: Manajer Pembelajaran, Kemahasiswaan, dan Alumni pada UT Yogyakarta | G45: suyatno@ecampus.ut.ac.id
F46: Manajer Pembelajaran, Kemahasiswaan, dan Alumni pada UT Bandar Lampung | G46: welli@ecampus.ut.ac.id
F47: Manajer Perluasan Daya Jangkau, Registrasi, dan Ujian pada UT Surabaya | G47: dwi@ecampus.ut.ac.id
F48: Manajer Pembelajaran, Kemahasiswaan, dan Alumni pada UT Surabaya | G48: hana@ecampus.ut.ac.id
F49: Manajer Perluasan Daya Jangkau, Registrasi, dan Ujian pada UT Jakarta | G49: melisa.arisanty@ecampus.ut.ac.id
F50: Manajer Perluasan Daya Jangkau, Registrasi, dan Ujian pada UT Bandung | G50: merry-monica@ecampus.ut.ac.id
F51: Manajer Pembelajaran, Kemahasiswaan, dan Alumni pada UT Jakarta | G51: selly@ecampus.ut.ac.id
... F82: Manajer Perluasan Daya Jangkau, Registrasi, dan Ujian pada UT Gorontalo | G82: yasirm@ecampus.ut.ac.id

Sheet email_id
A1: email | B1: id
A2: adrian@ecampus.ut.ac.id | B2: 1
A3: ali@ecampus.ut.ac.id | B3: 2
A4: sofjan@ecampus.ut.ac.id | B4: 3
A5: aguss@ecampus.ut.ac.id | B5: 4
A6: ake@ecampus.ut.ac.id | B6: 6
A7: sholihin@ecampus.ut.ac.id | B7: 8
A8: susiloe@ecampus.ut.ac.id | B8: 9
A9: andis@ecampus.ut.ac.id | B9: 10
A10: agussm@ecampus.ut.ac.id | B10: 11
A11: pakenp@ecampus.ut.ac.id | B11: 12
A12: timbul@ecampus.ut.ac.id | B12: 13
A13: ita@ecampus.ut.ac.id | B13: 14
... A7123: nur@ecampus.ut.ac.id | B7123: 33092

Sheet helper_user_ku
A1: id | B1: email | C1: kode_unit | D1: nip | E1: jabatan | F1: nama | G1: name_with_title
A2: 1 | B2: ali@ecampus.ut.ac.id | C2: UN31 | D2: 197208242000121001 | E2: Rektor | F2: Ali Muktiyanto | G2: Prof. Dr. Ali Muktiyanto, S.E., M.Si.
A3: 2 | B3: adrian@ecampus.ut.ac.id | C3: UN31.WR2 | D3: 197705032002121002 | E3: Wakil Rektor Bidang Keuangan, Sumber Daya, dan Umum | F3: Adrian Sutawijaya | G3: Dr. Adrian Sutawijaya, S.E., M.Si.
A4: 3 | B4: ian@ecampus.ut.ac.id | C4: UN31.WR4 | D4: 196901292000031003 | E4: Wakil Rektor Bidang Riset, Kerja Sama dan Bisnis | F4: Hendrian | G4: Dr. Hendrian, S.E., M.Si.
A5: 4 | B5: pakenp@ecampus.ut.ac.id | C5: UN31.WR3 | D5: 197008201997031003 | E5: Wakil Rektor Bidang Sistem Informasi, Layanan Jarak Jauh dan Alumni | F5: Paken Pandiangan | G5: Prof. Dr. Paken Pandiangan, S.Si., M.Si.
A6: 5 | B6: budiman@ecampus.ut.ac.id | C6: UN31.WR1 | D6: 197101161999031001 | E6: Wakil Rektor Bidang Akademik dan Kemahasiswaan | F6: Rahmat Budiman | G6: Prof. Rahmat Budiman, S.S., M.Hum., Ph.D.
A7: 6 | B7: dewi@ecampus.ut.ac.id | C7: UN31.LPPM | D7: 196107241987102003 | E7: Ketua Lembaga Penelitian dan Pengabdian Kepada Masyarakat | F7: Dewi Artati Padmo Putri | G7: Prof. Dra. Dewi Artati Padmo Putri, M.A., Ph.D.
A8: 7 | B8: enceng@ecampus.ut.ac.id | C8: UN31.UT15 | D8: 219600716202508101 | E8: Direktur Universitas Terbuka Bandung | F8: Enceng | G8: Drs Enceng, M. Si
A9: 8 | B9: mamanr@ecampus.ut.ac.id | C9: UN31.SPS | D9: 196305091989031002 | E9: Direktur Sekolah Pascasarjana | F9: Maman Rumanta | G9: Prof. Dr. Maman Rumanta, M.Si.
A10: 9 | B10: yunus@ecampus.ut.ac.id | C10: UN31.SVOK | D10: 196511101989031001 | E10: Direktur Sekolah Vokasi | F10: Mohamad Yunus | G10: Dr. Mohamad Yunus, S.S., M.A.
A11: 10 | B11: muzamil@ecampus.ut.ac.id | C11: UN31.UT12 | D11: 196109171987031002 | E11: Direktur Universitas Terbuka Jakarta | F11: Moh. Muzammil | G11: Drs. Moh. Muzammil, M.M.
A12: 11 | B12: naim@ecampus.ut.ac.id | C12: UN31.UT9 | D12: 219651029202511101 | E12: Direktur Universitas Terbuka Palembang | F12: Muhammad Tair A | G12: Drs. Muhammad Tair A, M.M.
A13: 12 | B13: nurma@ecampus.ut.ac.id | C13: UN31.FST | D13: 196705181991032001 | E13: Dekan Fakultas Sains dan Teknologi | F13: Subekti Nurmawati | G13: Dr. Subekti Nurmawati, M.Si.
... A2372: 2371 | B2372: mezu@ecampus.ut.ac.id | C2372: UN31.FHISIP | D2372: 119890210202307201 | E2372: Penata Dokumen Keuangan | F2372: Zumarie Putrimezu | G2372: Zumarie Putrimezu, S.E.

Sheet Sheet1
